Workbook
Name Category: 'Menu (Day 6 Ans)'!$C$2:$C$20
Name Category: OrderLines!$F$2:$F$925
Name ItemName: 'Menu (Day 6 Ans)'!$B$2:$B$20
Name OrderID: OrderLines!$A$2:$A$925
Name Qty: OrderLines!$C$2:$C$925
Name SKU: 'Menu (Day 6 Ans)'!$A$2:$A$20
Name SKU: OrderLines!$B$2:$B$925
Name Slicer_Branch1: #N/A
Name Slicer_Shift1: #N/A
Name SupplierID: 'Menu (Day 6 Ans)'!$D$2:$D$20
Name UnitCost: 'Menu (Day 6 Ans)'!$E$2:$E$20
Name UnitCost: OrderLines!$E$2:$E$925
Name UnitPrice: 'Menu (Day 6 Ans)'!$F$2:$F$20
Name UnitPrice: OrderLines!$D$2:$D$925

Sheet Orders
A1: OrderID | B1: OrderDateTime | C1: Branch | D1: CustomerType | E1: PaymentType | F1: Shift | G1: DiscountPct | H1: Revenue | I1: has beverage | J1: combo flag | K1: disc | L1: total cost | M1: profit | N1: Item list
A2: O00001 | B2: 45852.096 | C2: Head Office Café | D2: Visitor | E2: UPI | F2: Breakfast | G2: 0.06 | H2: =SUMIFS(OrderLines[LineNetAmount],OrderLines[OrderID],Orders[[#This Row],[OrderID]]) -> 147.909 | I2: =IF(COUNTIFS(OrderLines[OrderID],Orders[[#This Row],[OrderID]],OrderLines[Category],"Beverage"),"yes","no") -> no | J2: =IF(AND(COUNTIFS(OrderLines[OrderID],Orders[[#This Row],[OrderID]],OrderLines[Category],"Hot Meal"),Orders[[#This Row],[has beverage]]="yes"),"combo","single") -> single | K2: {=IF((SUMPRODUCT(OrderLines[UnitPrice],OrderLines[Qty],--(OrderLines[OrderID]=Orders[[#This Row],[OrderID]]))-Orders[[#This Row],[Revenue]])>40,"high disc","ok")} -> ok | L2: =SUMIFS(OrderLines[Food Cost],OrderLines[OrderID],Orders[[#This Row],[OrderID]]) -> 77.4 | M2: =Orders[[#This Row],[Revenue]]-Orders[[#This Row],[total cost]] -> 70.509 | N2: {=_xlfn.TEXTJOIN("+",,_xlfn._xlws.SORT(_xlfn.UNIQUE(_xlfn._xlws.FILTER(OrderLines[Category],OrderLines[OrderID]=Orders[[#This Row],[OrderID]]))))} -> Snack
A3: O00002 | B3: 45862.843 | C3: Plant 2 Canteen | D3: Staff | E3: Cash | F3: Dinner | G3: 0.05 | H3: =SUMIFS(OrderLines[LineNetAmount],OrderLines[OrderID],Orders[[#This Row],[OrderID]]) -> 101.5455 | I3: =IF(COUNTIFS(OrderLines[OrderID],Orders[[#This Row],[OrderID]],OrderLines[Category],"Beverage"),"yes","no") -> yes | J3: =IF(AND(COUNTIFS(OrderLines[OrderID],Orders[[#This Row],[OrderID]],OrderLines[Category],"Hot Meal"),Orders[[#This Row],[has beverage]]="yes"),"combo","single") -> single | K3: {=IF((SUMPRODUCT(OrderLines[UnitPrice],OrderLines[Qty],--(OrderLines[OrderID]=Orders[[#This Row],[OrderID]]))-Orders[[#This Row],[Revenue]])>40,"high disc","ok")} -> ok | L3: =SUMIFS(OrderLines[Food Cost],OrderLines[OrderID],Orders[[#This Row],[OrderID]]) -> 52.41 | M3: =Orders[[#This Row],[Revenue]]-Orders[[#This Row],[total cost]] -> 49.1355 | N3: {=_xlfn.TEXTJOIN("+",,_xlfn._xlws.SORT(_xlfn.UNIQUE(_xlfn._xlws.FILTER(OrderLines[Category],OrderLines[OrderID]=Orders[[#This Row],[OrderID]]))))} -> Beverage+Dessert
A4: O00003 | B4: 45848.661 | C4: Head Office Café | D4: Staff | E4: Card | F4: Lunch | G4: 0 | H4: =SUMIFS(OrderLines[LineNetAmount],OrderLines[OrderID],Orders[[#This Row],[OrderID]]) -> 668.96 | I4: =IF(COUNTIFS(OrderLines[OrderID],Orders[[#This Row],[OrderID]],OrderLines[Category],"Beverage"),"yes","no") -> yes | J4: =IF(AND(COUNTIFS(OrderLines[OrderID],Orders[[#This Row],[OrderID]],OrderLines[Category],"Hot Meal"),Orders[[#This Row],[has beverage]]="yes"),"combo","single") -> combo | K4: {=IF((SUMPRODUCT(OrderLines[UnitPrice],OrderLines[Qty],--(OrderLines[OrderID]=Orders[[#This Row],[OrderID]]))-Orders[[#This Row],[Revenue]])>40,"high disc","ok")} -> ok | L4: =SUMIFS(OrderLines[Food Cost],OrderLines[OrderID],Orders[[#This Row],[OrderID]]) -> 291.24 | M4: =Orders[[#This Row],[Revenue]]-Orders[[#This Row],[total cost]] -> 377.72 | N4: {=_xlfn.TEXTJOIN("+",,_xlfn._xlws.SORT(_xlfn.UNIQUE(_xlfn._xlws.FILTER(OrderLines[Category],OrderLines[OrderID]=Orders[[#This Row],[OrderID]]))))} -> Beverage+Hot Meal+Snack
A5: O00004 | B5: 45879.164 | C5: Plant 2 Canteen | D5: Visitor | E5: Cash | F5: Breakfast | G5: 0.03 | H5: =SUMIFS(OrderLines[LineNetAmount],OrderLines[OrderID],Orders[[#This Row],[OrderID]]) -> 477.4146 | I5: =IF(COUNTIFS(OrderLines[OrderID],Orders[[#This Row],[OrderID]],OrderLines[Category],"Beverage"),"yes","no") -> no | J5: =IF(AND(COUNTIFS(OrderLines[OrderID],Orders[[#This Row],[OrderID]],OrderLines[Category],"Hot Meal"),Orders[[#This Row],[has beverage]]="yes"),"combo","single") -> single | K5: {=IF((SUMPRODUCT(OrderLines[UnitPrice],OrderLines[Qty],--(OrderLines[OrderID]=Orders[[#This Row],[OrderID]]))-Orders[[#This Row],[Revenue]])>40,"high disc","ok")} -> ok | L5: =SUMIFS(OrderLines[Food Cost],OrderLines[OrderID],Orders[[#This Row],[OrderID]]) -> 224.16 | M5: =Orders[[#This Row],[Revenue]]-Orders[[#This Row],[total cost]] -> 253.2546 | N5: {=_xlfn.TEXTJOIN("+",,_xlfn._xlws.SORT(_xlfn.UNIQUE(_xlfn._xlws.FILTER(OrderLines[Category],OrderLines[OrderID]=Orders[[#This Row],[OrderID]]))))} -> Hot Meal
A6: O00005 | B6: 45845.135 | C6: Plant 2 Canteen | D6: Visitor | E6: Card | F6: Breakfast | G6: 0.04 | H6: =SUMIFS(OrderLines[LineNetAmount],OrderLines[OrderID],Orders[[#This Row],[OrderID]]) -> 95.0112 | I6: =IF(COUNTIFS(OrderLines[OrderID],Orders[[#This Row],[OrderID]],OrderLines[Category],"Beverage"),"yes","no") -> yes | J6: =IF(AND(COUNTIFS(OrderLines[OrderID],Orders[[#This Row],[OrderID]],OrderLines[Category],"Hot Meal"),Orders[[#This Row],[has beverage]]="yes"),"combo","single") -> single | K6: {=IF((SUMPRODUCT(OrderLines[UnitPrice],OrderLines[Qty],--(OrderLines[OrderID]=Orders[[#This Row],[OrderID]]))-Orders[[#This Row],[Revenue]])>40,"high disc","ok")} -> ok | L6: =SUMIFS(OrderLines[Food Cost],OrderLines[OrderID],Orders[[#This Row],[OrderID]]) -> 49.7 | M6: =Orders[[#This Row],[Revenue]]-Orders[[#This Row],[total cost]] -> 45.3112 | N6: {=_xlfn.TEXTJOIN("+",,_xlfn._xlws.SORT(_xlfn.UNIQUE(_xlfn._xlws.FILTER(OrderLines[Category],OrderLines[OrderID]=Orders[[#This Row],[OrderID]]))))} -> Beverage+Snack
A7: O00006 | B7: 45863.392 | C7: Plant 1 Canteen | D7: Worker | E7: UPI | F7: Breakfast | G7: 0.1 | H7: =SUMIFS(OrderLines[LineNetAmount],OrderLines[OrderID],Orders[[#This Row],[OrderID]]) -> 54.297 | I7: =IF(COUNTIFS(OrderLines[OrderID],Orders[[#This Row],[OrderID]],OrderLines[Category],"Beverage"),"yes","no") -> yes | J7: =IF(AND(COUNTIFS(OrderLines[OrderID],Orders[[#This Row],[OrderID]],OrderLines[Category],"Hot Meal"),Orders[[#This Row],[has beverage]]="yes"),"combo","single") -> single | K7: {=IF((SUMPRODUCT(OrderLines[UnitPrice],OrderLines[Qty],--(OrderLines[OrderID]=Orders[[#This Row],[OrderID]]))-Orders[[#This Row],[Revenue]])>40,"high disc","ok")} -> ok | L7: =SUMIFS(OrderLines[Food Cost],OrderLines[OrderID],Orders[[#This Row],[OrderID]]) -> 24 | M7: =Orders[[#This Row],[Revenue]]-Orders[[#This Row],[total cost]] -> 30.297 | N7: {=_xlfn.TEXTJOIN("+",,_xlfn._xlws.SORT(_xlfn.UNIQUE(_xlfn._xlws.FILTER(OrderLines[Category],OrderLines[OrderID]=Orders[[#This Row],[OrderID]]))))} -> Beverage
A8: O00007 | B8: 45852.86 | C8: Plant 2 Canteen | D8: Worker | E8: Card | F8: Dinner | G8: 0.07 | H8: =SUMIFS(OrderLines[LineNetAmount],OrderLines[OrderID],Orders[[#This Row],[OrderID]]) -> 348.4152 | I8: =IF(COUNTIFS(OrderLines[OrderID],Orders[[#This Row],[OrderID]],OrderLines[Category],"Beverage"),"yes","no") -> yes | J8: =IF(AND(COUNTIFS(OrderLines[OrderID],Orders[[#This Row],[OrderID]],OrderLines[Category],"Hot Meal"),Orders[[#This Row],[has beverage]]="yes"),"combo","single") -> combo | K8: {=IF((SUMPRODUCT(OrderLines[UnitPrice],OrderLines[Qty],--(OrderLines[OrderID]=Orders[[#This Row],[OrderID]]))-Orders[[#This Row],[Revenue]])>40,"high disc","ok")} -> ok | L8: =SUMIFS(OrderLines[Food Cost],OrderLines[OrderID],Orders[[#This Row],[OrderID]]) -> 159.98 | M8: =Orders[[#This Row],[Revenue]]-Orders[[#This Row],[total cost]] -> 188.4352 | N8: {=_xlfn.TEXTJOIN("+",,_xlfn._xlws.SORT(_xlfn.UNIQUE(_xlfn._xlws.FILTER(OrderLines[Category],OrderLines[OrderID]=Orders[[#This Row],[OrderID]]))))} -> Beverage+Hot Meal
A9: O00008 | B9: 45863.504 | C9: Plant 1 Canteen | D9: Staff | E9: UPI | F9: Lunch | G9: 0 | H9: =SUMIFS(OrderLines[LineNetAmount],OrderLines[OrderID],Orders[[#This Row],[OrderID]]) -> 223.75 | I9: =IF(COUNTIFS(OrderLines[OrderID],Orders[[#This Row],[OrderID]],OrderLines[Category],"Beverage"),"yes","no") -> yes | J9: =IF(AND(COUNTIFS(OrderLines[OrderID],Orders[[#This Row],[OrderID]],OrderLines[Category],"Hot Meal"),Orders[[#This Row],[has beverage]]="yes"),"combo","single") -> single | K9: {=IF((SUMPRODUCT(OrderLines[UnitPrice],OrderLines[Qty],--(OrderLines[OrderID]=Orders[[#This Row],[OrderID]]))-Orders[[#This Row],[Revenue]])>40,"high disc","ok")} -> ok | L9: =SUMIFS(OrderLines[Food Cost],OrderLines[OrderID],Orders[[#This Row],[OrderID]]) -> 110.98 | M9: =Orders[[#This Row],[Revenue]]-Orders[[#This Row],[total cost]] -> 112.77 | N9: {=_xlfn.TEXTJOIN("+",,_xlfn._xlws.SORT(_xlfn.UNIQUE(_xlfn._xlws.FILTER(OrderLines[Category],OrderLines[OrderID]=Orders[[#This Row],[OrderID]]))))} -> Beverage+Dessert
A10: O00009 | B10: 45844.162 | C10: Head Office Café | D10: Visitor | E10: Cash | F10: Breakfast | G10: 0.07 | H10: =SUMIFS(OrderLines[LineNetAmount],OrderLines[OrderID],Orders[[#This Row],[OrderID]]) -> 459.2898 | I10: =IF(COUNTIFS(OrderLines[OrderID],Orders[[#This Row],[OrderID]],OrderLines[Category],"Beverage"),"yes","no") -> no | J10: =IF(AND(COUNTIFS(OrderLines[OrderID],Orders[[#This Row],[OrderID]],OrderLines[Category],"Hot Meal"),Orders[[#This Row],[has beverage]]="yes"),"combo","single") -> single | K10: {=IF((SUMPRODUCT(OrderLines[UnitPrice],OrderLines[Qty],--(OrderLines[OrderID]=Orders[[#This Row],[OrderID]]))-Orders[[#This Row],[Revenue]])>40,"high disc","ok")} -> ok | L10: =SUMIFS(OrderLines[Food Cost],OrderLines[OrderID],Orders[[#This Row],[OrderID]]) -> 225.97 | M10: =Orders[[#This Row],[Revenue]]-Orders[[#This Row],[total cost]] -> 233.3198 | N10: {=_xlfn.TEXTJOIN("+",,_xlfn._xlws.SORT(_xlfn.UNIQUE(_xlfn._xlws.FILTER(OrderLines[Category],OrderLines[OrderID]=Orders[[#This Row],[OrderID]]))))} -> Dessert+Hot Meal+Snack
A11: O00010 | B11: 45862.2 | C11: Plant 1 Canteen | D11: Staff | E11: Card | F11: Breakfast | G11: 0.04 | H11: =SUMIFS(OrderLines[LineNetAmount],OrderLines[OrderID],Orders[[#This Row],[OrderID]]) -> 420.0768 | I11: =IF(COUNTIFS(OrderLines[OrderID],Orders[[#This Row],[OrderID]],OrderLines[Category],"Beverage"),"yes","no") -> yes | J11: =IF(AND(COUNTIFS(OrderLines[OrderID],Orders[[#This Row],[OrderID]],OrderLines[Category],"Hot Meal"),Orders[[#This Row],[has beverage]]="yes"),"combo","single") -> combo | K11: {=IF((SUMPRODUCT(OrderLines[UnitPrice],OrderLines[Qty],--(OrderLines[OrderID]=Orders[[#This Row],[OrderID]]))-Orders[[#This Row],[Revenue]])>40,"high disc","ok")} -> ok | L11: =SUMIFS(OrderLines[Food Cost],OrderLines[OrderID],Orders[[#This Row],[OrderID]]) -> 204.88 | M11: =Orders[[#This Row],[Revenue]]-Orders[[#This Row],[total cost]] -> 215.1968 | N11: {=_xlfn.TEXTJOIN("+",,_xlfn._xlws.SORT(_xlfn.UNIQUE(_xlfn._xlws.FILTER(OrderLines[Category],OrderLines[OrderID]=Orders[[#This Row],[OrderID]]))))} -> Beverage+Dessert+Hot Meal+Snack
A12: O00011 | B12: 45860.003 | C12: Plant 2 Canteen | D12: Worker | E12: Cash | F12: Breakfast | G12: 0.03 | H12: =SUMIFS(OrderLines[LineNetAmount],OrderLines[OrderID],Orders[[#This Row],[OrderID]]) -> 27.5771 | I12: =IF(COUNTIFS(OrderLines[OrderID],Orders[[#This Row],[OrderID]],OrderLines[Category],"Beverage"),"yes","no") -> yes | J12: =IF(AND(COUNTIFS(OrderLines[OrderID],Orders[[#This Row],[OrderID]],OrderLines[Category],"Hot Meal"),Orders[[#This Row],[has beverage]]="yes"),"combo","single") -> single | K12: {=IF((SUMPRODUCT(OrderLines[UnitPrice],OrderLines[Qty],--(OrderLines[OrderID]=Orders[[#This Row],[OrderID]]))-Orders[[#This Row],[Revenue]])>40,"high disc","ok")} -> ok | L12: =SUMIFS(OrderLines[Food Cost],OrderLines[OrderID],Orders[[#This Row],[OrderID]]) -> 13.89 | M12: =Orders[[#This Row],[Revenue]]-Orders[[#This Row],[total cost]] -> 13.6871 | N12: {=_xlfn.TEXTJOIN("+",,_xlfn._xlws.SORT(_xlfn.UNIQUE(_xlfn._xlws.FILTER(OrderLines[Category],OrderLines[OrderID]=Orders[[#This Row],[OrderID]]))))} -> Beverage
A13: O00012 | B13: 45839.459 | C13: Plant 2 Canteen | D13: Staff | E13: Card | F13: Lunch | G13: 0.08 | H13: =SUMIFS(OrderLines[LineNetAmount],OrderLines[OrderID],Orders[[#This Row],[OrderID]]) -> 98.118 | I13: =IF(COUNTIFS(OrderLines[OrderID],Orders[[#This Row],[OrderID]],OrderLines[Category],"Beverage"),"yes","no") -> no | J13: =IF(AND(COUNTIFS(OrderLines[OrderID],Orders[[#This Row],[OrderID]],OrderLines[Category],"Hot Meal"),Orders[[#This Row],[has beverage]]="yes"),"combo","single") -> single | K13: {=IF((SUMPRODUCT(OrderLines[UnitPrice],OrderLines[Qty],--(OrderLines[OrderID]=Orders[[#This Row],[OrderID]]))-Orders[[#This Row],[Revenue]])>40,"high disc","ok")} -> ok | L13: =SUMIFS(OrderLines[Food Cost],OrderLines[OrderID],Orders[[#This Row],[OrderID]]) -> 47.75 | M13: =Orders[[#This Row],[Revenue]]-Orders[[#This Row],[total cost]] -> 50.368 | N13: {=_xlfn.TEXTJOIN("+",,_xlfn._xlws.SORT(_xlfn.UNIQUE(_xlfn._xlws.FILTER(OrderLines[Category],OrderLines[OrderID]=Orders[[#This Row],[OrderID]]))))} -> Dessert+Snack
... A361: O00360 | B361: 45878.689 | C361: Plant 2 Canteen | D361: Visitor | E361: UPI | F361: Dinner | G361: 0.04 | H361: =SUMIFS(OrderLines[LineNetAmount],OrderLines[OrderID],Orders[[#This Row],[OrderID]]) -> 962.1504 | I361: =IF(COUNTIFS(OrderLines[OrderID],Orders[[#This Row],[OrderID]],OrderLines[Category],"Beverage"),"yes","no") -> yes | J361: =IF(AND(COUNTIFS(OrderLines[OrderID],Orders[[#This Row],[OrderID]],OrderLines[Category],"Hot Meal"),Orders[[#This Row],[has beverage]]="yes"),"combo","single") -> combo | K361: {=IF((SUMPRODUCT(OrderLines[UnitPrice],OrderLines[Qty],--(OrderLines[OrderID]=Orders[[#This Row],[OrderID]]))-Orders[[#This Row],[Revenue]])>40,"high disc","ok")} -> high disc | L361: =SUMIFS(OrderLines[Food Cost],OrderLines[OrderID],Orders[[#This Row],[OrderID]]) -> 466.15 | M361: =Orders[[#This Row],[Revenue]]-Orders[[#This Row],[total cost]] -> 496.0004 | N361: {=_xlfn.TEXTJOIN("+",,_xlfn._xlws.SORT(_xlfn.UNIQUE(_xlfn._xlws.FILTER(OrderLines[Category],OrderLines[OrderID]=Orders[[#This Row],[OrderID]]))))} -> Beverage+Hot Meal

Sheet OrderLines
A1: OrderID | B1: SKU | C1: Qty | D1: UnitPrice | E1: UnitCost | F1: Category | G1: Item category | H1: OrderDateTime | I1: Branch | J1: DiscountPct | K1: PaymentType | L1: Shift | M1: LineNetAmount | N1: Combo Flag | O1: DiscountFlag | P1: Food Cost | Q1: Gross Profit
A2: O00001 | B2: SHJ7XV | C2: 3 | D2: {=VLOOKUP(OrderLines[[#This Row],[SKU]:[SKU]],Menu[],MATCH(OrderLines[[#Headers],[UnitPrice]],Menu[#Headers],0),FALSE)} -> 52.45 | E2: {=VLOOKUP(OrderLines[[#This Row],[SKU]:[SKU]],Menu[],MATCH(OrderLines[[#Headers],[UnitCost]],Menu[#Headers],0),FALSE)} -> 25.8 | F2: {=VLOOKUP(OrderLines[[#This Row],[SKU]:[SKU]],Menu[],MATCH(OrderLines[[#Headers],[Category]],Menu[#Headers],0),FALSE)} -> Snack | G2: {=_xlfn.TEXTJOIN("+",TRUE,_xlfn._xlws.SORT(_xlfn.UNIQUE(_xlfn._xlws.FILTER(OrderLines[Category],OrderLines[OrderID]=OrderLines[[#This Row],[OrderID]]))))} -> Snack | H2: {=INT(VLOOKUP(OrderLines[[#This Row],[OrderID]:[OrderID]],Orders[],MATCH(OrderLines[[#Headers],[OrderDateTime]],Orders[#Headers],0),FALSE))} -> 45852 | I2: {=VLOOKUP(OrderLines[[#This Row],[OrderID]:[OrderID]],Orders[],MATCH(OrderLines[[#Headers],[Branch]],Orders[#Headers],0),FALSE)} -> Head Office Café | J2: {=VLOOKUP(OrderLines[[#This Row],[OrderID]:[OrderID]],Orders[],MATCH(OrderLines[[#Headers],[DiscountPct]],Orders[#Headers],0),FALSE)} -> 0.06 | K2: {=VLOOKUP(OrderLines[[#This Row],[OrderID]:[OrderID]],Orders[],MATCH(OrderLines[[#Headers],[PaymentType]],Orders[#Headers],0),FALSE)} -> UPI | L2: {=VLOOKUP(OrderLines[[#This Row],[OrderID]:[OrderID]],Orders[],MATCH(OrderLines[[#Headers],[Shift]],Orders[#Headers],0),FALSE)} -> Breakfast | M2: =(OrderLines[[#This Row],[Qty]]*OrderLines[[#This Row],[UnitPrice]])*(1-OrderLines[[#This Row],[DiscountPct]]) -> 147.909 | N2: =IF(AND(COUNTIFS(OrderLines[OrderID],OrderLines[[#This Row],[OrderID]],OrderLines[Category],"Hot Meal"),COUNTIFS(OrderLines[OrderID],OrderLines[[#This Row],[OrderID]],OrderLines[Category],"Beverage")),"Combo","Single") -> Single | O2: {=IF(SUMPRODUCT(OrderLines[UnitPrice],OrderLines[Qty],OrderLines[DiscountPct],--(OrderLines[OrderID] = OrderLines[[#This Row],[OrderID]]))>40,"High Discount","Ok")} -> Ok | P2: =OrderLines[[#This Row],[UnitCost]]*OrderLines[[#This Row],[Qty]] -> 77.4 | Q2: =OrderLines[[#This Row],[LineNetAmount]]-OrderLines[[#This Row],[Food Cost]] -> 70.509
A3: O00002 | B3: BTIQJ7 | C3: 1 | D3: {=VLOOKUP(OrderLines[[#This Row],[SKU]:[SKU]],Menu[],MATCH(OrderLines[[#Headers],[UnitPrice]],Menu[#Headers],0),FALSE)} -> 30.34 | E3: {=VLOOKUP(OrderLines[[#This Row],[SKU]:[SKU]],Menu[],MATCH(OrderLines[[#Headers],[UnitCost]],Menu[#Headers],0),FALSE)} -> 14.18 | F3: {=VLOOKUP(OrderLines[[#This Row],[SKU]:[SKU]],Menu[],MATCH(OrderLines[[#Headers],[Category]],Menu[#Headers],0),FALSE)} -> Beverage | G3: {=_xlfn.TEXTJOIN("+",TRUE,_xlfn._xlws.SORT(_xlfn.UNIQUE(_xlfn._xlws.FILTER(OrderLines[Category],OrderLines[OrderID]=OrderLines[[#This Row],[OrderID]]))))} -> Beverage+Dessert | H3: {=INT(VLOOKUP(OrderLines[[#This Row],[OrderID]:[OrderID]],Orders[],MATCH(OrderLines[[#Headers],[OrderDateTime]],Orders[#Headers],0),FALSE))} -> 45862 | I3: {=VLOOKUP(OrderLines[[#This Row],[OrderID]:[OrderID]],Orders[],MATCH(OrderLines[[#Headers],[Branch]],Orders[#Headers],0),FALSE)} -> Plant 2 Canteen | J3: {=VLOOKUP(OrderLines[[#This Row],[OrderID]:[OrderID]],Orders[],MATCH(OrderLines[[#Headers],[DiscountPct]],Orders[#Headers],0),FALSE)} -> 0.05 | K3: {=VLOOKUP(OrderLines[[#This Row],[OrderID]:[OrderID]],Orders[],MATCH(OrderLines[[#Headers],[PaymentType]],Orders[#Headers],0),FALSE)} -> Cash | L3: {=VLOOKUP(OrderLines[[#This Row],[OrderID]:[OrderID]],Orders[],MATCH(OrderLines[[#Headers],[Shift]],Orders[#Headers],0),FALSE)} -> Dinner | M3: =(OrderLines[[#This Row],[Qty]]*OrderLines[[#This Row],[UnitPrice]])*(1-OrderLines[[#This Row],[DiscountPct]]) -> 28.823 | N3: =IF(AND(COUNTIFS(OrderLines[OrderID],OrderLines[[#This Row],[OrderID]],OrderLines[Category],"Hot Meal"),COUNTIFS(OrderLines[OrderID],OrderLines[[#This Row],[OrderID]],OrderLines[Category],"Beverage")),"Combo","Single") -> Single | O3: {=IF(SUMPRODUCT(OrderLines[UnitPrice],OrderLines[Qty],OrderLines[DiscountPct],--(OrderLines[OrderID] = OrderLines[[#This Row],[OrderID]]))>40,"High Discount","Ok")} -> Ok | P3: =OrderLines[[#This Row],[UnitCost]]*OrderLines[[#This Row],[Qty]] -> 14.18 | Q3: =OrderLines[[#This Row],[LineNetAmount]]-OrderLines[[#This Row],[Food Cost]] -> 14.643
A4: O00002 | B4: DH9SDB | C4: 1 | D4: {=VLOOKUP(OrderLines[[#This Row],[SKU]:[SKU]],Menu[],MATCH(OrderLines[[#Headers],[UnitPrice]],Menu[#Headers],0),FALSE)} -> 76.55 | E4: {=VLOOKUP(OrderLines[[#This Row],[SKU]:[SKU]],Menu[],MATCH(OrderLines[[#Headers],[UnitCost]],Menu[#Headers],0),FALSE)} -> 38.23 | F4: {=VLOOKUP(OrderLines[[#This Row],[SKU]:[SKU]],Menu[],MATCH(OrderLines[[#Headers],[Category]],Menu[#Headers],0),FALSE)} -> Dessert | G4: {=_xlfn.TEXTJOIN("+",TRUE,_xlfn._xlws.SORT(_xlfn.UNIQUE(_xlfn._xlws.FILTER(OrderLines[Category],OrderLines[OrderID]=OrderLines[[#This Row],[OrderID]]))))} -> Beverage+Dessert | H4: {=INT(VLOOKUP(OrderLines[[#This Row],[OrderID]:[OrderID]],Orders[],MATCH(OrderLines[[#Headers],[OrderDateTime]],Orders[#Headers],0),FALSE))} -> 45862 | I4: {=VLOOKUP(OrderLines[[#This Row],[OrderID]:[OrderID]],Orders[],MATCH(OrderLines[[#Headers],[Branch]],Orders[#Headers],0),FALSE)} -> Plant 2 Canteen | J4: {=VLOOKUP(OrderLines[[#This Row],[OrderID]:[OrderID]],Orders[],MATCH(OrderLines[[#Headers],[DiscountPct]],Orders[#Headers],0),FALSE)} -> 0.05 | K4: {=VLOOKUP(OrderLines[[#This Row],[OrderID]:[OrderID]],Orders[],MATCH(OrderLines[[#Headers],[PaymentType]],Orders[#Headers],0),FALSE)} -> Cash | L4: {=VLOOKUP(OrderLines[[#This Row],[OrderID]:[OrderID]],Orders[],MATCH(OrderLines[[#Headers],[Shift]],Orders[#Headers],0),FALSE)} -> Dinner | M4: =(OrderLines[[#This Row],[Qty]]*OrderLines[[#This Row],[UnitPrice]])*(1-OrderLines[[#This Row],[DiscountPct]]) -> 72.7225 | N4: =IF(AND(COUNTIFS(OrderLines[OrderID],OrderLines[[#This Row],[OrderID]],OrderLines[Category],"Hot Meal"),COUNTIFS(OrderLines[OrderID],OrderLines[[#This Row],[OrderID]],OrderLines[Category],"Beverage")),"Combo","Single") -> Single | O4: {=IF(SUMPRODUCT(OrderLines[UnitPrice],OrderLines[Qty],OrderLines[DiscountPct],--(OrderLines[OrderID] = OrderLines[[#This Row],[OrderID]]))>40,"High Discount","Ok")} -> Ok | P4: =OrderLines[[#This Row],[UnitCost]]*OrderLines[[#This Row],[Qty]] -> 38.23 | Q4: =OrderLines[[#This Row],[LineNetAmount]]-OrderLines[[#This Row],[Food Cost]] -> 34.4925
A5: O00003 | B5: BOC6UZ | C5: 2 | D5: {=VLOOKUP(OrderLines[[#This Row],[SKU]:[SKU]],Menu[],MATCH(OrderLines[[#Headers],[UnitPrice]],Menu[#Headers],0),FALSE)} -> 32.98 | E5: {=VLOOKUP(OrderLines[[#This Row],[SKU]:[SKU]],Menu[],MATCH(OrderLines[[#Headers],[UnitCost]],Menu[#Headers],0),FALSE)} -> 11.84 | F5: {=VLOOKUP(OrderLines[[#This Row],[SKU]:[SKU]],Menu[],MATCH(OrderLines[[#Headers],[Category]],Menu[#Headers],0),FALSE)} -> Beverage | G5: {=_xlfn.TEXTJOIN("+",TRUE,_xlfn._xlws.SORT(_xlfn.UNIQUE(_xlfn._xlws.FILTER(OrderLines[Category],OrderLines[OrderID]=OrderLines[[#This Row],[OrderID]]))))} -> Beverage+Hot Meal+Snack | H5: {=INT(VLOOKUP(OrderLines[[#This Row],[OrderID]:[OrderID]],Orders[],MATCH(OrderLines[[#Headers],[OrderDateTime]],Orders[#Headers],0),FALSE))} -> 45848 | I5: {=VLOOKUP(OrderLines[[#This Row],[OrderID]:[OrderID]],Orders[],MATCH(OrderLines[[#Headers],[Branch]],Orders[#Headers],0),FALSE)} -> Head Office Café | J5: {=VLOOKUP(OrderLines[[#This Row],[OrderID]:[OrderID]],Orders[],MATCH(OrderLines[[#Headers],[DiscountPct]],Orders[#Headers],0),FALSE)} -> 0 | K5: {=VLOOKUP(OrderLines[[#This Row],[OrderID]:[OrderID]],Orders[],MATCH(OrderLines[[#Headers],[PaymentType]],Orders[#Headers],0),FALSE)} -> Card | L5: {=VLOOKUP(OrderLines[[#This Row],[OrderID]:[OrderID]],Orders[],MATCH(OrderLines[[#Headers],[Shift]],Orders[#Headers],0),FALSE)} -> Lunch | M5: =(OrderLines[[#This Row],[Qty]]*OrderLines[[#This Row],[UnitPrice]])*(1-OrderLines[[#This Row],[DiscountPct]]) -> 65.96 | N5: =IF(AND(COUNTIFS(OrderLines[OrderID],OrderLines[[#This Row],[OrderID]],OrderLines[Category],"Hot Meal"),COUNTIFS(OrderLines[OrderID],OrderLines[[#This Row],[OrderID]],OrderLines[Category],"Beverage")),"Combo","Single") -> Combo | O5: {=IF(SUMPRODUCT(OrderLines[UnitPrice],OrderLines[Qty],OrderLines[DiscountPct],--(OrderLines[OrderID] = OrderLines[[#This Row],[OrderID]]))>40,"High Discount","Ok")} -> Ok | P5: =OrderLines[[#This Row],[UnitCost]]*OrderLines[[#This Row],[Qty]] -> 23.68 | Q5: =OrderLines[[#This Row],[LineNetAmount]]-OrderLines[[#This Row],[Food Cost]] -> 42.28
A6: O00003 | B6: SHJ7XV | C6: 1 | D6: {=VLOOKUP(OrderLines[[#This Row],[SKU]:[SKU]],Menu[],MATCH(OrderLines[[#Headers],[UnitPrice]],Menu[#Headers],0),FALSE)} -> 52.45 | E6: {=VLOOKUP(OrderLines[[#This Row],[SKU]:[SKU]],Menu[],MATCH(OrderLines[[#Headers],[UnitCost]],Menu[#Headers],0),FALSE)} -> 25.8 | F6: {=VLOOKUP(OrderLines[[#This Row],[SKU]:[SKU]],Menu[],MATCH(OrderLines[[#Headers],[Category]],Menu[#Headers],0),FALSE)} -> Snack | G6: {=_xlfn.TEXTJOIN("+",TRUE,_xlfn._xlws.SORT(_xlfn.UNIQUE(_xlfn._xlws.FILTER(OrderLines[Category],OrderLines[OrderID]=OrderLines[[#This Row],[OrderID]]))))} -> Beverage+Hot Meal+Snack | H6: {=INT(VLOOKUP(OrderLines[[#This Row],[OrderID]:[OrderID]],Orders[],MATCH(OrderLines[[#Headers],[OrderDateTime]],Orders[#Headers],0),FALSE))} -> 45848 | I6: {=VLOOKUP(OrderLines[[#This Row],[OrderID]:[OrderID]],Orders[],MATCH(OrderLines[[#Headers],[Branch]],Orders[#Headers],0),FALSE)} -> Head Office Café | J6: {=VLOOKUP(OrderLines[[#This Row],[OrderID]:[OrderID]],Orders[],MATCH(OrderLines[[#Headers],[DiscountPct]],Orders[#Headers],0),FALSE)} -> 0 | K6: {=VLOOKUP(OrderLines[[#This Row],[OrderID]:[OrderID]],Orders[],MATCH(OrderLines[[#Headers],[PaymentType]],Orders[#Headers],0),FALSE)} -> Card | L6: {=VLOOKUP(OrderLines[[#This Row],[OrderID]:[OrderID]],Orders[],MATCH(OrderLines[[#Headers],[Shift]],Orders[#Headers],0),FALSE)} -> Lunch | M6: =(OrderLines[[#This Row],[Qty]]*OrderLines[[#This Row],[UnitPrice]])*(1-OrderLines[[#This Row],[DiscountPct]]) -> 52.45 | N6: =IF(AND(COUNTIFS(OrderLines[OrderID],OrderLines[[#This Row],[OrderID]],OrderLines[Category],"Hot Meal"),COUNTIFS(OrderLines[OrderID],OrderLines[[#This Row],[OrderID]],OrderLines[Category],"Beverage")),"Combo","Single") -> Combo | O6: {=IF(SUMPRODUCT(OrderLines[UnitPrice],OrderLines[Qty],OrderLines[DiscountPct],--(OrderLines[OrderID] = OrderLines[[#This Row],[OrderID]]))>40,"High Discount","Ok")} -> Ok | P6: =OrderLines[[#This Row],[UnitCost]]*OrderLines[[#This Row],[Qty]] -> 25.8 | Q6: =OrderLines[[#This Row],[LineNetAmount]]-OrderLines[[#This Row],[Food Cost]] -> 26.65
A7: O00003 | B7: H3A3ZM | C7: 3 | D7: {=VLOOKUP(OrderLines[[#This Row],[SKU]:[SKU]],Menu[],MATCH(OrderLines[[#Headers],[UnitPrice]],Menu[#Headers],0),FALSE)} -> 170.83 | E7: {=VLOOKUP(OrderLines[[#This Row],[SKU]:[SKU]],Menu[],MATCH(OrderLines[[#Headers],[UnitCost]],Menu[#Headers],0),FALSE)} -> 74.07 | F7: {=VLOOKUP(OrderLines[[#This Row],[SKU]:[SKU]],Menu[],MATCH(OrderLines[[#Headers],[Category]],Menu[#Headers],0),FALSE)} -> Hot Meal | G7: {=_xlfn.TEXTJOIN("+",TRUE,_xlfn._xlws.SORT(_xlfn.UNIQUE(_xlfn._xlws.FILTER(OrderLines[Category],OrderLines[OrderID]=OrderLines[[#This Row],[OrderID]]))))} -> Beverage+Hot Meal+Snack | H7: {=INT(VLOOKUP(OrderLines[[#This Row],[OrderID]:[OrderID]],Orders[],MATCH(OrderLines[[#Headers],[OrderDateTime]],Orders[#Headers],0),FALSE))} -> 45848 | I7: {=VLOOKUP(OrderLines[[#This Row],[OrderID]:[OrderID]],Orders[],MATCH(OrderLines[[#Headers],[Branch]],Orders[#Headers],0),FALSE)} -> Head Office Café | J7: {=VLOOKUP(OrderLines[[#This Row],[OrderID]:[OrderID]],Orders[],MATCH(OrderLines[[#Headers],[DiscountPct]],Orders[#Headers],0),FALSE)} -> 0 | K7: {=VLOOKUP(OrderLines[[#This Row],[OrderID]:[OrderID]],Orders[],MATCH(OrderLines[[#Headers],[PaymentType]],Orders[#Headers],0),FALSE)} -> Card | L7: {=VLOOKUP(OrderLines[[#This Row],[OrderID]:[OrderID]],Orders[],MATCH(OrderLines[[#Headers],[Shift]],Orders[#Headers],0),FALSE)} -> Lunch | M7: =(OrderLines[[#This Row],[Qty]]*OrderLines[[#This Row],[UnitPrice]])*(1-OrderLines[[#This Row],[DiscountPct]]) -> 512.49 | N7: =IF(AND(COUNTIFS(OrderLines[OrderID],OrderLines[[#This Row],[OrderID]],OrderLines[Category],"Hot Meal"),COUNTIFS(OrderLines[OrderID],OrderLines[[#This Row],[OrderID]],OrderLines[Category],"Beverage")),"Combo","Single") -> Combo | O7: {=IF(SUMPRODUCT(OrderLines[UnitPrice],OrderLines[Qty],OrderLines[DiscountPct],--(OrderLines[OrderID] = OrderLines[[#This Row],[OrderID]]))>40,"High Discount","Ok")} -> Ok | P7: =OrderLines[[#This Row],[UnitCost]]*OrderLines[[#This Row],[Qty]] -> 222.21 | Q7: =OrderLines[[#This Row],[LineNetAmount]]-OrderLines[[#This Row],[Food Cost]] -> 290.28
A8: O00003 | B8: SZBIKC | C8: 1 | D8: {=VLOOKUP(OrderLines[[#This Row],[SKU]:[SKU]],Menu[],MATCH(OrderLines[[#Headers],[UnitPrice]],Menu[#Headers],0),FALSE)} -> 38.06 | E8: {=VLOOKUP(OrderLines[[#This Row],[SKU]:[SKU]],Menu[],MATCH(OrderLines[[#Headers],[UnitCost]],Menu[#Headers],0),FALSE)} -> 19.55 | F8: {=VLOOKUP(OrderLines[[#This Row],[SKU]:[SKU]],Menu[],MATCH(OrderLines[[#Headers],[Category]],Menu[#Headers],0),FALSE)} -> Snack | G8: {=_xlfn.TEXTJOIN("+",TRUE,_xlfn._xlws.SORT(_xlfn.UNIQUE(_xlfn._xlws.FILTER(OrderLines[Category],OrderLines[OrderID]=OrderLines[[#This Row],[OrderID]]))))} -> Beverage+Hot Meal+Snack | H8: {=INT(VLOOKUP(OrderLines[[#This Row],[OrderID]:[OrderID]],Orders[],MATCH(OrderLines[[#Headers],[OrderDateTime]],Orders[#Headers],0),FALSE))} -> 45848 | I8: {=VLOOKUP(OrderLines[[#This Row],[OrderID]:[OrderID]],Orders[],MATCH(OrderLines[[#Headers],[Branch]],Orders[#Headers],0),FALSE)} -> Head Office Café | J8: {=VLOOKUP(OrderLines[[#This Row],[OrderID]:[OrderID]],Orders[],MATCH(OrderLines[[#Headers],[DiscountPct]],Orders[#Headers],0),FALSE)} -> 0 | K8: {=VLOOKUP(OrderLines[[#This Row],[OrderID]:[OrderID]],Orders[],MATCH(OrderLines[[#Headers],[PaymentType]],Orders[#Headers],0),FALSE)} -> Card | L8: {=VLOOKUP(OrderLines[[#This Row],[OrderID]:[OrderID]],Orders[],MATCH(OrderLines[[#Headers],[Shift]],Orders[#Headers],0),FALSE)} -> Lunch | M8: =(OrderLines[[#This Row],[Qty]]*OrderLines[[#This Row],[UnitPrice]])*(1-OrderLines[[#This Row],[DiscountPct]]) -> 38.06 | N8: =IF(AND(COUNTIFS(OrderLines[OrderID],OrderLines[[#This Row],[OrderID]],OrderLines[Category],"Hot Meal"),COUNTIFS(OrderLines[OrderID],OrderLines[[#This Row],[OrderID]],OrderLines[Category],"Beverage")),"Combo","Single") -> Combo | O8: {=IF(SUMPRODUCT(OrderLines[UnitPrice],OrderLines[Qty],OrderLines[DiscountPct],--(OrderLines[OrderID] = OrderLines[[#This Row],[OrderID]]))>40,"High Discount","Ok")} -> Ok | P8: =OrderLines[[#This Row],[UnitCost]]*OrderLines[[#This Row],[Qty]] -> 19.55 | Q8: =OrderLines[[#This Row],[LineNetAmount]]-OrderLines[[#This Row],[Food Cost]] -> 18.51
A9: O00004 | B9: HH1DNM | C9: 2 | D9: {=VLOOKUP(OrderLines[[#This Row],[SKU]:[SKU]],Menu[],MATCH(OrderLines[[#Headers],[UnitPrice]],Menu[#Headers],0),FALSE)} -> 246.09 | E9: {=VLOOKUP(OrderLines[[#This Row],[SKU]:[SKU]],Menu[],MATCH(OrderLines[[#Headers],[UnitCost]],Menu[#Headers],0),FALSE)} -> 112.08 | F9: {=VLOOKUP(OrderLines[[#This Row],[SKU]:[SKU]],Menu[],MATCH(OrderLines[[#Headers],[Category]],Menu[#Headers],0),FALSE)} -> Hot Meal | G9: {=_xlfn.TEXTJOIN("+",TRUE,_xlfn._xlws.SORT(_xlfn.UNIQUE(_xlfn._xlws.FILTER(OrderLines[Category],OrderLines[OrderID]=OrderLines[[#This Row],[OrderID]]))))} -> Hot Meal | H9: {=INT(VLOOKUP(OrderLines[[#This Row],[OrderID]:[OrderID]],Orders[],MATCH(OrderLines[[#Headers],[OrderDateTime]],Orders[#Headers],0),FALSE))} -> 45879 | I9: {=VLOOKUP(OrderLines[[#This Row],[OrderID]:[OrderID]],Orders[],MATCH(OrderLines[[#Headers],[Branch]],Orders[#Headers],0),FALSE)} -> Plant 2 Canteen | J9: {=VLOOKUP(OrderLines[[#This Row],[OrderID]:[OrderID]],Orders[],MATCH(OrderLines[[#Headers],[DiscountPct]],Orders[#Headers],0),FALSE)} -> 0.03 | K9: {=VLOOKUP(OrderLines[[#This Row],[OrderID]:[OrderID]],Orders[],MATCH(OrderLines[[#Headers],[PaymentType]],Orders[#Headers],0),FALSE)} -> Cash | L9: {=VLOOKUP(OrderLines[[#This Row],[OrderID]:[OrderID]],Orders[],MATCH(OrderLines[[#Headers],[Shift]],Orders[#Headers],0),FALSE)} -> Breakfast | M9: =(OrderLines[[#This Row],[Qty]]*OrderLines[[#This Row],[UnitPrice]])*(1-OrderLines[[#This Row],[DiscountPct]]) -> 477.4146 | N9: =IF(AND(COUNTIFS(OrderLines[OrderID],OrderLines[[#This Row],[OrderID]],OrderLines[Category],"Hot Meal"),COUNTIFS(OrderLines[OrderID],OrderLines[[#This Row],[OrderID]],OrderLines[Category],"Beverage")),"Combo","Single") -> Single | O9: {=IF(SUMPRODUCT(OrderLines[UnitPrice],OrderLines[Qty],OrderLines[DiscountPct],--(OrderLines[OrderID] = OrderLines[[#This Row],[OrderID]]))>40,"High Discount","Ok")} -> Ok | P9: =OrderLines[[#This Row],[UnitCost]]*OrderLines[[#This Row],[Qty]] -> 224.16 | Q9: =OrderLines[[#This Row],[LineNetAmount]]-OrderLines[[#This Row],[Food Cost]] -> 253.2546
A10: O00005 | B10: SCKW5N | C10: 1 | D10: {=VLOOKUP(OrderLines[[#This Row],[SKU]:[SKU]],Menu[],MATCH(OrderLines[[#Headers],[UnitPrice]],Menu[#Headers],0),FALSE)} -> 70.54 | E10: {=VLOOKUP(OrderLines[[#This Row],[SKU]:[SKU]],Menu[],MATCH(OrderLines[[#Headers],[UnitCost]],Menu[#Headers],0),FALSE)} -> 35.81 | F10: {=VLOOKUP(OrderLines[[#This Row],[SKU]:[SKU]],Menu[],MATCH(OrderLines[[#Headers],[Category]],Menu[#Headers],0),FALSE)} -> Snack | G10: {=_xlfn.TEXTJOIN("+",TRUE,_xlfn._xlws.SORT(_xlfn.UNIQUE(_xlfn._xlws.FILTER(OrderLines[Category],OrderLines[OrderID]=OrderLines[[#This Row],[OrderID]]))))} -> Beverage+Snack | H10: {=INT(VLOOKUP(OrderLines[[#This Row],[OrderID]:[OrderID]],Orders[],MATCH(OrderLines[[#Headers],[OrderDateTime]],Orders[#Headers],0),FALSE))} -> 45845 | I10: {=VLOOKUP(OrderLines[[#This Row],[OrderID]:[OrderID]],Orders[],MATCH(OrderLines[[#Headers],[Branch]],Orders[#Headers],0),FALSE)} -> Plant 2 Canteen | J10: {=VLOOKUP(OrderLines[[#This Row],[OrderID]:[OrderID]],Orders[],MATCH(OrderLines[[#Headers],[DiscountPct]],Orders[#Headers],0),FALSE)} -> 0.04 | K10: {=VLOOKUP(OrderLines[[#This Row],[OrderID]:[OrderID]],Orders[],MATCH(OrderLines[[#Headers],[PaymentType]],Orders[#Headers],0),FALSE)} -> Card | L10: {=VLOOKUP(OrderLines[[#This Row],[OrderID]:[OrderID]],Orders[],MATCH(OrderLines[[#Headers],[Shift]],Orders[#Headers],0),FALSE)} -> Breakfast | M10: =(OrderLines[[#This Row],[Qty]]*OrderLines[[#This Row],[UnitPrice]])*(1-OrderLines[[#This Row],[DiscountPct]]) -> 67.7184 | N10: =IF(AND(COUNTIFS(OrderLines[OrderID],OrderLines[[#This Row],[OrderID]],OrderLines[Category],"Hot Meal"),COUNTIFS(OrderLines[OrderID],OrderLines[[#This Row],[OrderID]],OrderLines[Category],"Beverage")),"Combo","Single") -> Single | O10: {=IF(SUMPRODUCT(OrderLines[UnitPrice],OrderLines[Qty],OrderLines[DiscountPct],--(OrderLines[OrderID] = OrderLines[[#This Row],[OrderID]]))>40,"High Discount","Ok")} -> Ok | P10: =OrderLines[[#This Row],[UnitCost]]*OrderLines[[#This Row],[Qty]] -> 35.81 | Q10: =OrderLines[[#This Row],[LineNetAmount]]-OrderLines[[#This Row],[Food Cost]] -> 31.9084
A11: O00005 | B11: B0T0PV | C11: 1 | D11: {=VLOOKUP(OrderLines[[#This Row],[SKU]:[SKU]],Menu[],MATCH(OrderLines[[#Headers],[UnitPrice]],Menu[#Headers],0),FALSE)} -> 28.43 | E11: {=VLOOKUP(OrderLines[[#This Row],[SKU]:[SKU]],Menu[],MATCH(OrderLines[[#Headers],[UnitCost]],Menu[#Headers],0),FALSE)} -> 13.89 | F11: {=VLOOKUP(OrderLines[[#This Row],[SKU]:[SKU]],Menu[],MATCH(OrderLines[[#Headers],[Category]],Menu[#Headers],0),FALSE)} -> Beverage | G11: {=_xlfn.TEXTJOIN("+",TRUE,_xlfn._xlws.SORT(_xlfn.UNIQUE(_xlfn._xlws.FILTER(OrderLines[Category],OrderLines[OrderID]=OrderLines[[#This Row],[OrderID]]))))} -> Beverage+Snack | H11: {=INT(VLOOKUP(OrderLines[[#This Row],[OrderID]:[OrderID]],Orders[],MATCH(OrderLines[[#Headers],[OrderDateTime]],Orders[#Headers],0),FALSE))} -> 45845 | I11: {=VLOOKUP(OrderLines[[#This Row],[OrderID]:[OrderID]],Orders[],MATCH(OrderLines[[#Headers],[Branch]],Orders[#Headers],0),FALSE)} -> Plant 2 Canteen | J11: {=VLOOKUP(OrderLines[[#This Row],[OrderID]:[OrderID]],Orders[],MATCH(OrderLines[[#Headers],[DiscountPct]],Orders[#Headers],0),FALSE)} -> 0.04 | K11: {=VLOOKUP(OrderLines[[#This Row],[OrderID]:[OrderID]],Orders[],MATCH(OrderLines[[#Headers],[PaymentType]],Orders[#Headers],0),FALSE)} -> Card | L11: {=VLOOKUP(OrderLines[[#This Row],[OrderID]:[OrderID]],Orders[],MATCH(OrderLines[[#Headers],[Shift]],Orders[#Headers],0),FALSE)} -> Breakfast | M11: =(OrderLines[[#This Row],[Qty]]*OrderLines[[#This Row],[UnitPrice]])*(1-OrderLines[[#This Row],[DiscountPct]]) -> 27.2928 | N11: =IF(AND(COUNTIFS(OrderLines[OrderID],OrderLines[[#This Row],[OrderID]],OrderLines[Category],"Hot Meal"),COUNTIFS(OrderLines[OrderID],OrderLines[[#This Row],[OrderID]],OrderLines[Category],"Beverage")),"Combo","Single") -> Single | O11: {=IF(SUMPRODUCT(OrderLines[UnitPrice],OrderLines[Qty],OrderLines[DiscountPct],--(OrderLines[OrderID] = OrderLines[[#This Row],[OrderID]]))>40,"High Discount","Ok")} -> Ok | P11: =OrderLines[[#This Row],[UnitCost]]*OrderLines[[#This Row],[Qty]] -> 13.89 | Q11: =OrderLines[[#This Row],[LineNetAmount]]-OrderLines[[#This Row],[Food Cost]] -> 13.4028
A12: O00006 | B12: BXO6QJ | C12: 3 | D12: {=VLOOKUP(OrderLines[[#This Row],[SKU]:[SKU]],Menu[],MATCH(OrderLines[[#Headers],[UnitPrice]],Menu[#Headers],0),FALSE)} -> 20.11 | E12: {=VLOOKUP(OrderLines[[#This Row],[SKU]:[SKU]],Menu[],MATCH(OrderLines[[#Headers],[UnitCost]],Menu[#Headers],0),FALSE)} -> 8 | F12: {=VLOOKUP(OrderLines[[#This Row],[SKU]:[SKU]],Menu[],MATCH(OrderLines[[#Headers],[Category]],Menu[#Headers],0),FALSE)} -> Beverage | G12: {=_xlfn.TEXTJOIN("+",TRUE,_xlfn._xlws.SORT(_xlfn.UNIQUE(_xlfn._xlws.FILTER(OrderLines[Category],OrderLines[OrderID]=OrderLines[[#This Row],[OrderID]]))))} -> Beverage | H12: {=INT(VLOOKUP(OrderLines[[#This Row],[OrderID]:[OrderID]],Orders[],MATCH(OrderLines[[#Headers],[OrderDateTime]],Orders[#Headers],0),FALSE))} -> 45863 | I12: {=VLOOKUP(OrderLines[[#This Row],[OrderID]:[OrderID]],Orders[],MATCH(OrderLines[[#Headers],[Branch]],Orders[#Headers],0),FALSE)} -> Plant 1 Canteen | J12: {=VLOOKUP(OrderLines[[#This Row],[OrderID]:[OrderID]],Orders[],MATCH(OrderLines[[#Headers],[DiscountPct]],Orders[#Headers],0),FALSE)} -> 0.1 | K12: {=VLOOKUP(OrderLines[[#This Row],[OrderID]:[OrderID]],Orders[],MATCH(OrderLines[[#Headers],[PaymentType]],Orders[#Headers],0),FALSE)} -> UPI | L12: {=VLOOKUP(OrderLines[[#This Row],[OrderID]:[OrderID]],Orders[],MATCH(OrderLines[[#Headers],[Shift]],Orders[#Headers],0),FALSE)} -> Breakfast | M12: =(OrderLines[[#This Row],[Qty]]*OrderLines[[#This Row],[UnitPrice]])*(1-OrderLines[[#This Row],[DiscountPct]]) -> 54.297 | N12: =IF(AND(COUNTIFS(OrderLines[OrderID],OrderLines[[#This Row],[OrderID]],OrderLines[Category],"Hot Meal"),COUNTIFS(OrderLines[OrderID],OrderLines[[#This Row],[OrderID]],OrderLines[Category],"Beverage")),"Combo","Single") -> Single | O12: {=IF(SUMPRODUCT(OrderLines[UnitPrice],OrderLines[Qty],OrderLines[DiscountPct],--(OrderLines[OrderID] = OrderLines[[#This Row],[OrderID]]))>40,"High Discount","Ok")} -> Ok | P12: =OrderLines[[#This Row],[UnitCost]]*OrderLines[[#This Row],[Qty]] -> 24 | Q12: =OrderLines[[#This Row],[LineNetAmount]]-OrderLines[[#This Row],[Food Cost]] -> 30.297
A13: O00007 | B13: BOC6UZ | C13: 1 | D13: {=VLOOKUP(OrderLines[[#This Row],[SKU]:[SKU]],Menu[],MATCH(OrderLines[[#Headers],[UnitPrice]],Menu[#Headers],0),FALSE)} -> 32.98 | E13: {=VLOOKUP(OrderLines[[#This Row],[SKU]:[SKU]],Menu[],MATCH(OrderLines[[#Headers],[UnitCost]],Menu[#Headers],0),FALSE)} -> 11.84 | F13: {=VLOOKUP(OrderLines[[#This Row],[SKU]:[SKU]],Menu[],MATCH(OrderLines[[#Headers],[Category]],Menu[#Headers],0),FALSE)} -> Beverage | G13: {=_xlfn.TEXTJOIN("+",TRUE,_xlfn._xlws.SORT(_xlfn.UNIQUE(_xlfn._xlws.FILTER(OrderLines[Category],OrderLines[OrderID]=OrderLines[[#This Row],[OrderID]]))))} -> Beverage+Hot Meal | H13: {=INT(VLOOKUP(OrderLines[[#This Row],[OrderID]:[OrderID]],Orders[],MATCH(OrderLines[[#Headers],[OrderDateTime]],Orders[#Headers],0),FALSE))} -> 45852 | I13: {=VLOOKUP(OrderLines[[#This Row],[OrderID]:[OrderID]],Orders[],MATCH(OrderLines[[#Headers],[Branch]],Orders[#Headers],0),FALSE)} -> Plant 2 Canteen | J13: {=VLOOKUP(OrderLines[[#This Row],[OrderID]:[OrderID]],Orders[],MATCH(OrderLines[[#Headers],[DiscountPct]],Orders[#Headers],0),FALSE)} -> 0.07 | K13: {=VLOOKUP(OrderLines[[#This Row],[OrderID]:[OrderID]],Orders[],MATCH(OrderLines[[#Headers],[PaymentType]],Orders[#Headers],0),FALSE)} -> Card | L13: {=VLOOKUP(OrderLines[[#This Row],[OrderID]:[OrderID]],Orders[],MATCH(OrderLines[[#Headers],[Shift]],Orders[#Headers],0),FALSE)} -> Dinner | M13: =(OrderLines[[#This Row],[Qty]]*OrderLines[[#This Row],[UnitPrice]])*(1-OrderLines[[#This Row],[DiscountPct]]) -> 30.6714 | N13: =IF(AND(COUNTIFS(OrderLines[OrderID],OrderLines[[#This Row],[OrderID]],OrderLines[Category],"Hot Meal"),COUNTIFS(OrderLines[OrderID],OrderLines[[#This Row],[OrderID]],OrderLines[Category],"Beverage")),"Combo","Single") -> Combo | O13: {=IF(SUMPRODUCT(OrderLines[UnitPrice],OrderLines[Qty],OrderLines[DiscountPct],--(OrderLines[OrderID] = OrderLines[[#This Row],[OrderID]]))>40,"High Discount","Ok")} -> Ok | P13: =OrderLines[[#This Row],[UnitCost]]*OrderLines[[#This Row],[Qty]] -> 11.84 | Q13: =OrderLines[[#This Row],[LineNetAmount]]-OrderLines[[#This Row],[Food Cost]] -> 18.8314
... A925: O00360 | B925: BTIQJ7 | C925: 2 | D925: {=VLOOKUP(OrderLines[[#This Row],[SKU]:[SKU]],Menu[],MATCH(OrderLines[[#Headers],[UnitPrice]],Menu[#Headers],0),FALSE)} -> 30.34 | E925: {=VLOOKUP(OrderLines[[#This Row],[SKU]:[SKU]],Menu[],MATCH(OrderLines[[#Headers],[UnitCost]],Menu[#Headers],0),FALSE)} -> 14.18 | F925: {=VLOOKUP(OrderLines[[#This Row],[SKU]:[SKU]],Menu[],MATCH(OrderLines[[#Headers],[Category]],Menu[#Headers],0),FALSE)} -> Beverage | G925: {=_xlfn.TEXTJOIN("+",TRUE,_xlfn._xlws.SORT(_xlfn.UNIQUE(_xlfn._xlws.FILTER(OrderLines[Category],OrderLines[OrderID]=OrderLines[[#This Row],[OrderID]]))))} -> Beverage+Hot Meal | H925: {=INT(VLOOKUP(OrderLines[[#This Row],[OrderID]:[OrderID]],Orders[],MATCH(OrderLines[[#Headers],[OrderDateTime]],Orders[#Headers],0),FALSE))} -> 45878 | I925: {=VLOOKUP(OrderLines[[#This Row],[OrderID]:[OrderID]],Orders[],MATCH(OrderLines[[#Headers],[Branch]],Orders[#Headers],0),FALSE)} -> Plant 2 Canteen | J925: {=VLOOKUP(OrderLines[[#This Row],[OrderID]:[OrderID]],Orders[],MATCH(OrderLines[[#Headers],[DiscountPct]],Orders[#Headers],0),FALSE)} -> 0.04 | K925: {=VLOOKUP(OrderLines[[#This Row],[OrderID]:[OrderID]],Orders[],MATCH(OrderLines[[#Headers],[PaymentType]],Orders[#Headers],0),FALSE)} -> UPI | L925: {=VLOOKUP(OrderLines[[#This Row],[OrderID]:[OrderID]],Orders[],MATCH(OrderLines[[#Headers],[Shift]],Orders[#Headers],0),FALSE)} -> Dinner | M925: =(OrderLines[[#This Row],[Qty]]*OrderLines[[#This Row],[UnitPrice]])*(1-OrderLines[[#This Row],[DiscountPct]]) -> 58.2528 | N925: =IF(AND(COUNTIFS(OrderLines[OrderID],OrderLines[[#This Row],[OrderID]],OrderLines[Category],"Hot Meal"),COUNTIFS(OrderLines[OrderID],OrderLines[[#This Row],[OrderID]],OrderLines[Category],"Beverage")),"Combo","Single") -> Combo | O925: {=IF(SUMPRODUCT(OrderLines[UnitPrice],OrderLines[Qty],OrderLines[DiscountPct],--(OrderLines[OrderID] = OrderLines[[#This Row],[OrderID]]))>40,"High Discount","Ok")} -> High Discount | P925: =OrderLines[[#This Row],[UnitCost]]*OrderLines[[#This Row],[Qty]] -> 28.36 | Q925: =OrderLines[[#This Row],[LineNetAmount]]-OrderLines[[#This Row],[Food Cost]] -> 29.8928

Sheet pivot charts
A1: 1 | B1: total combo orders | D1: all orders
B2: {=COUNTA(_xlfn.UNIQUE(_xlfn._xlws.FILTER(OrderLines[OrderID],OrderLines[Combo Flag]="Combo")))} -> 86 | D2: =COUNTA(_xlfn.UNIQUE(OrderLines[OrderID])) -> 360
C4: combo order as % of all order
C5: =B2/D2 -> 0.23888889
A8: combo rev | B8: =SUMIFS(OrderLines[LineNetAmount],OrderLines[Combo Flag],"Combo") -> 46800.541
A9: avg tkt size | B9: {=SUMIFS(OrderLines[LineNetAmount],OrderLines[Combo Flag],"Combo")/COUNTA(_xlfn.UNIQUE(_xlfn._xlws.FILTER(OrderLines[OrderID],OrderLines[Combo Flag]="Combo")))} -> 544.19233
A11: combo profit | B11: =SUMIFS(OrderLines[Gross Profit],OrderLines[Combo Flag],"Combo") -> 23976.601
A12: avg gp/combo order | B12: {=SUMIFS(OrderLines[Gross Profit],OrderLines[Combo Flag],"Combo")/COUNTA(_xlfn.UNIQUE(_xlfn._xlws.FILTER(OrderLines[OrderID],OrderLines[Combo Flag]="Combo")))} -> 278.79768
A17: 2 | B17: Combo flag | C17: total rev | D17: orderid count | E17: avg tkt size | F17: avg total foodcost | G17: avg gp | H17: Gross margin% | M17: Row Labels | N17: Sum of LineNetAmount | O17: Sum of Food Cost | P17: Sum of Gross Profit | Q17: Distinct Count of OrderID
B18: Combo | C18: =SUMIFS(OrderLines[LineNetAmount],OrderLines[Combo Flag],B18) -> 46800.541 | D18: {=COUNTA(_xlfn.UNIQUE(_xlfn._xlws.FILTER(OrderLines[OrderID],OrderLines[Combo Flag]=B18)))} -> 86 | E18: {=SUMIFS(OrderLines[LineNetAmount],OrderLines[Combo Flag],B18)/COUNTA(_xlfn.UNIQUE(_xlfn._xlws.FILTER(OrderLines[OrderID],OrderLines[Combo Flag]=B18)))} -> 544.19233 | F18: {=SUMIFS(OrderLines[Food Cost],OrderLines[Combo Flag],B18)/COUNTA(_xlfn.UNIQUE(_xlfn._xlws.FILTER(OrderLines[OrderID],OrderLines[Combo Flag]=B18)))} -> 265.39465 | G18: {=SUMIFS(OrderLines[Gross Profit],OrderLines[Combo Flag],B18)/COUNTA(_xlfn.UNIQUE(_xlfn._xlws.FILTER(OrderLines[OrderID],OrderLines[Combo Flag]=B18)))} -> 278.79768 | H18: =SUMIFS(OrderLines[Gross Profit],OrderLines[Combo Flag],B18)/SUMIFS(OrderLines[LineNetAmount],OrderLines[Combo Flag],B18) -> 0.51231461 | M18: Combo | N18: 46800.541 | O18: 22823.94 | P18: 23976.601 | Q18: 86
B19: Single | C19: =SUMIFS(OrderLines[LineNetAmount],OrderLines[Combo Flag],B19) -> 85847.09 | D19: {=COUNTA(_xlfn.UNIQUE(_xlfn._xlws.FILTER(OrderLines[OrderID],OrderLines[Combo Flag]=B19)))} -> 274 | E19: {=SUMIFS(OrderLines[LineNetAmount],OrderLines[Combo Flag],B19)/COUNTA(_xlfn.UNIQUE(_xlfn._xlws.FILTER(OrderLines[OrderID],OrderLines[Combo Flag]=B19)))} -> 313.31055 | F19: {=SUMIFS(OrderLines[Food Cost],OrderLines[Combo Flag],B19)/COUNTA(_xlfn.UNIQUE(_xlfn._xlws.FILTER(OrderLines[OrderID],OrderLines[Combo Flag]=B19)))} -> 154.47212 | G19: {=SUMIFS(OrderLines[Gross Profit],OrderLines[Combo Flag],B19)/COUNTA(_xlfn.UNIQUE(_xlfn._xlws.FILTER(OrderLines[OrderID],OrderLines[Combo Flag]=B19)))} -> 158.83843 | H19: =SUMIFS(OrderLines[Gross Profit],OrderLines[Combo Flag],B19)/SUMIFS(OrderLines[LineNetAmount],OrderLines[Combo Flag],B19) -> 0.50696803 | M19: Single | N19: 85847.09 | O19: 42325.36 | P19: 43521.73 | Q19: 274
B20: Gap | C20: =C18-C19 -> -39046.549 | D20: =D18-D19 -> -188 | E20: =E18-E19 -> 230.88179 | F20: =F18-F19 -> 110.92253 | G20: =G18-G19 -> 119.95925 | H20: =H18-H19 -> 0.0053465805 | M20: Grand Total | N20: 132647.63 | O20: 65149.3 | P20: 67498.331 | Q20: 360
N22: Avg Tkt Size | O22: Avg Food Cost | P22: Avg Gross Profit | Q22: gm%
M23: Combo | N23: =N18/$Q18 -> 544.19233 | O23: =O18/$Q18 -> 265.39465 | P23: =P18/$Q18 -> 278.79768 | Q23: =P18/N18 -> 0.51231461
M24: Single | N24: =N19/$Q19 -> 313.31055 | O24: =O19/$Q19 -> 154.47212 | P24: =P19/$Q19 -> 158.83843 | Q24: =P19/N19 -> 0.50696803
M25: Gap | N25: =N23-N24 -> 230.88179 | O25: =O23-O24 -> 110.92253 | P25: =P23-P24 -> 119.95925 | Q25: =Q23-Q24 -> 0.0053465805
N30: Gross margin%
M31: Combo | N31: =Q23 -> 0.51231461
M32: Single | N32: =Q24 -> 0.50696803
M33: Gap | N33: =Q25 -> 0.0053465805
A38: 4 | B38: Distinct Count of OrderID | C38: Column Labels
B39: Row Labels | C39: Combo
B40: Breakfast | C40: 1
B41: Grand Total | C41: 1
A47: 3 | B47: Distinct Count of OrderID | C47: Column Labels
B48: Row Labels | C48: Combo
B49: Plant 1 Canteen | C49: 0.1744186
B50: Head Office Café | C50: 0.40697674
B51: Plant 2 Canteen | C51: 0.41860465
B52: Grand Total | C52: 1
A56: 5 | B56: Categories Combination | C56: Orders | E56: Categories Combination | F56: Orders
B57: Beverage | C57: 34 | E57: =B57 -> Beverage | F57: =C57 -> 34
B58: Beverage+Snack | C58: 31 | E58: =B58 -> Beverage+Snack | F58: =C58 -> 31
B59: Snack | C59: 29 | E59: =B59 -> Snack | F59: =C59 -> 29
B60: Hot Meal+Snack | C60: 28 | E60: =B60 -> Hot Meal+Snack | F60: =C60 -> 28
B61: Hot Meal | C61: 27 | E61: =B61 -> Hot Meal | F61: =C61 -> 27
B62: Dessert+Hot Meal | C62: 27 | E62: =B62 -> Dessert+Hot Meal | F62: =C62 -> 27
B63: Beverage+Dessert+Hot Meal | C63: 27 | E63: =B63 -> Beverage+Dessert+Hot Meal | F63: =C63 -> 27
B64: Beverage+Hot Meal+Snack | C64: 25 | E64: =B64 -> Beverage+Hot Meal+Snack | F64: =C64 -> 25
B65: Beverage+Hot Meal | C65: 25 | E65: =B65 -> Beverage+Hot Meal | F65: =C65 -> 25
...

Sheet Dashboard
A2: FOOD & BEVERAGE BUSINESS PERFORMANCE DASHBOARD (JULY-AUGUST 2025)
B6: Combo Orders | G6: Combo Orders % | L6: Avg Ticket Size | Q6: Avg Gross Profit/Combo | V6: Total Orders | AA6: Gross Margin%
B8: ='pivot charts'!B93 -> 86 | G8: ='pivot charts'!F93 -> 0.23888889 | L8: ='pivot charts'!J92 -> 544.19233 | Q8: ='pivot charts'!N92 -> 278.79768 | V8: ='pivot charts'!P92 -> 360 | AA8: ='pivot charts'!C107 -> 0.51231461
O27: INTERACTIVE PROFITABILITY SIMULATOR | AF27: Values | AG27: Combo | AH27: Single | AI27: Difference %
AF29: Avg Revenue | AG29: ='pivot charts'!C104 -> 544.19233 | AH29: ='pivot charts'!D104 -> 313.31055 | AI29: ='pivot charts'!E104 -> 0.73691036
P30: SELECT A HOT MEAL | U30: SELECT A BEVERAGE | Z30: ENTER A DISCOUNT%
AF31: Avg Cost | AG31: ='pivot charts'!C105 -> 265.39465 | AH31: ='pivot charts'!D105 -> 154.47212 | AI31: ='pivot charts'!E105 -> 0.7180748
P32: Rajma Chawal | U32: Bottled Water | Z32: 0.05
AF33: Avg Profit | AG33: ='pivot charts'!C106 -> 278.79768 | AH33: ='pivot charts'!D106 -> 158.83843 | AI33: ='pivot charts'!E106 -> 0.75522814
P35: FOOD COST | U35: NET SELLING PRICE | Z35: GROSS PROFIT | AF35: GM% | AG35: ='pivot charts'!C107 -> 0.51231461 | AH35: ='pivot charts'!D107 -> 0.50696803 | AI35: ='pivot charts'!E107 -> 0.0053465805
P37: {=SUM(_xlfn._xlws.FILTER(Menu[UnitCost],Menu[ItemName]=$P$32),_xlfn._xlws.FILTER(Menu[UnitCost],Menu[ItemName]=$U$32))} -> 94.81 | U37: {=(SUM(_xlfn._xlws.FILTER(Menu[UnitPrice],Menu[ItemName]=$P$32),_xlfn._xlws.FILTER(Menu[UnitPrice],Menu[ItemName]=$U$32)))*(1-$Z$32)} -> 166.0885 | Z37: =$U$37-$P$37 -> 71.2785
AF38: Combo Vs Single
R40: GROSS MARGIN% | X40: CURRENT BEVERAGE STOCK
R42: =$Z$37/$U$37 -> 0.42915976 | X42: =_xlfn.XLOOKUP($U$32,Inventory[ItemName],Inventory[OnHandQty],"Not Available",0) -> 199

Sheet Day 2 Ans
B1: 1 | C1: Line net amount | D1: =SUM(OrderLines[LineNetAmount]) -> 132647.63
L3: Row Labels | M3: Sum of Revenue2 | N3: Sum of Revenue
B4: 2 | C4: July revenue | D4: =SUMIFS(OrderLines[LineNetAmount],OrderLines[OrderDateTime],">=2025-7-1",OrderLines[OrderDateTime],"<=2025-7-31") -> 63939.191 | F4: MOM% | G4: =(D5-D4)/D4 -> 0.07459039 | L4: Jul | M4: 63939.191
C5: August revenue | D5: =SUMIFS(OrderLines[LineNetAmount],OrderLines[OrderDateTime],">=2025-8-1",OrderLines[OrderDateTime],"<=2025-8-31") -> 68708.44 | L5: Aug | M5: 68708.44 | N5: 0.07459039
L7: Shift | M7: (All)
L8: Branch | M8: (All)
B9: 3 | C9: =SUMIFS(OrderLines[LineNetAmount],OrderLines[Branch],"Head Office Café",OrderLines[Shift],"Lunch",OrderLines[OrderDateTime],">=2025-08-01",OrderLines[OrderDateTime],"<=2025-08-31") -> 7403.6595
L10: Row Labels | M10: Sum of Revenue
L11: Aug | M11: 68708.44
B13: 4 | C13: {=COUNTA(_xlfn.UNIQUE(_xlfn._xlws.FILTER(OrderLines[OrderID],(OrderLines[Category]="Beverage")*(OrderLines[PaymentType]="UPI"))))} -> 70 | L13: has beverage | M13: yes
L15: Row Labels | M15: Count of OrderID
C16: Shift | L16: UPI | M16: 70
B17: 5 | C17: Breakfast | D17: {=SUMIFS(OrderLines[LineNetAmount],OrderLines[Shift],C17)/COUNTA(_xlfn.UNIQUE(_xlfn._xlws.FILTER(OrderLines[OrderID],OrderLines[Shift]=C17)))} -> 360.57145
C18: Lunch | D18: {=SUMIFS(OrderLines[LineNetAmount],OrderLines[Shift],C18)/COUNTA(_xlfn.UNIQUE(_xlfn._xlws.FILTER(OrderLines[OrderID],OrderLines[Shift]=C18)))} -> 372.02587
C19: Dinner | D19: {=SUMIFS(OrderLines[LineNetAmount],OrderLines[Shift],C19)/COUNTA(_xlfn.UNIQUE(_xlfn._xlws.FILTER(OrderLines[OrderID],OrderLines[Shift]=C19)))} -> 378.80541
M20: Row Labels | N20: Average of Revenue
M21: Breakfast | N21: 360.57145
M22: Dinner | N22: 378.80541
M23: Lunch | N23: 372.02587

Sheet Day 4 Ans
A2: 1
B3: Branch | C3: Values
B4: Head Office Café | D4: Plant 1 Canteen | F4: Plant 2 Canteen
A5: Category | B5: Revenue | C5: Sum of LineNetAmount | D5: Revenue | E5: Sum of LineNetAmount | F5: Revenue | G5: Sum of LineNetAmount
A6: Beverage | B6: 0.071247851 | C6: 3489.8727 | D6: 0.087079621 | E6: 2895.3357 | F6: 0.078081063 | G6: 3936.5499
A7: Dessert | B7: 0.19484685 | C7: 9544.0172 | D7: 0.19542264 | E7: 6497.6642 | F7: 0.16888445 | G7: 8514.5112
A8: Hot Meal | B8: 0.62481557 | C8: 30604.808 | D8: 0.52355178 | E8: 17407.726 | F8: 0.61734407 | G8: 31124.138
A9: Snack | B9: 0.10908973 | C9: 5343.449 | D9: 0.19394596 | E9: 6448.5657 | F9: 0.13569041 | G9: 6840.9941
A10: Grand Total | B10: 1 | C10: 48982.147 | D10: 1 | E10: 33249.291 | F10: 1 | G10: 50416.193
A12: 2
A13: Month | B13: Aug | G13: 3
G14: Branch | H14: GM% | I14: Sum of LineNetAmount
A15: SKU | B15: Revenue | C15: Quantity | G15: Head Office Café | H15: 0.50999942 | I15: 48982.147
A16: HXAJI0 | B16: 10470.06 | C16: 49 | G16: Plant 1 Canteen | H16: 0.4971165 | I16: 33249.291
A17: HDPBHS | B17: 9230.7763 | C17: 38 | G17: Plant 2 Canteen | H17: 0.51548305 | I17: 50416.193
A18: HH1DNM | B18: 8283.3894 | C18: 36
A19: HUZZPQ | B19: 6563.112 | C19: 48
A20: H3A3ZM | B20: 5927.801 | C20: 37
A21: D9T84A | B21: 4925.456 | C21: 45
A22: DH9SDB | B22: 3714.9715 | C22: 52
A23: SCKW5N | B23: 2910.4804 | C23: 44
A24: DFFYVN | B24: 2362.578 | C24: 46
A25: S5NQ4F | B25: 2318.778 | C25: 49
A26: Grand Total | B26: 56707.403 | C26: 444

Sheet Daily Summary
B1: Date | C1: Revenue | D1: Avg Feedback Rating | E1: Avg waste cost
B2: {=_xlfn.SEQUENCE(DATEDIF(DATE(2025,7,1),DATE(2025,8,31),"d")+1,1,DATE(2025,7,1),1)} -> 45839 | C2: =SUMIFS(OrderLines[LineNetAmount],OrderLines[OrderDateTime],$B2) -> 198.822 | D2: =IFERROR(AVERAGEIFS(Feedback[Rating],Feedback[Date],$B2),0) -> 3.8571429 | E2: =IFERROR(ROUND(AVERAGEIFS(WasteLog[Waste cost],WasteLog[Date],$B2),2),0) -> 0
B3: 45840 | C3: =SUMIFS(OrderLines[LineNetAmount],OrderLines[OrderDateTime],$B3) -> 3202.85 | D3: =IFERROR(AVERAGEIFS(Feedback[Rating],Feedback[Date],$B3),0) -> 3.6 | E3: =IFERROR(ROUND(AVERAGEIFS(WasteLog[Waste cost],WasteLog[Date],$B3),2),0) -> 92.48
B4: 45841 | C4: =SUMIFS(OrderLines[LineNetAmount],OrderLines[OrderDateTime],$B4) -> 1027.7541 | D4: =IFERROR(AVERAGEIFS(Feedback[Rating],Feedback[Date],$B4),0) -> 4 | E4: =IFERROR(ROUND(AVERAGEIFS(WasteLog[Waste cost],WasteLog[Date],$B4),2),0) -> 0
B5: 45842 | C5: =SUMIFS(OrderLines[LineNetAmount],OrderLines[OrderDateTime],$B5) -> 1622.0684 | D5: =IFERROR(AVERAGEIFS(Feedback[Rating],Feedback[Date],$B5),0) -> 4.5 | E5: =IFERROR(ROUND(AVERAGEIFS(WasteLog[Waste cost],WasteLog[Date],$B5),2),0) -> 80.92
B6: 45843 | C6: =SUMIFS(OrderLines[LineNetAmount],OrderLines[OrderDateTime],$B6) -> 626.2479 | D6: =IFERROR(AVERAGEIFS(Feedback[Rating],Feedback[Date],$B6),0) -> 4 | E6: =IFERROR(ROUND(AVERAGEIFS(WasteLog[Waste cost],WasteLog[Date],$B6),2),0) -> 84.55
B7: 45844 | C7: =SUMIFS(OrderLines[LineNetAmount],OrderLines[OrderDateTime],$B7) -> 2758.1276 | D7: =IFERROR(AVERAGEIFS(Feedback[Rating],Feedback[Date],$B7),0) -> 3.5 | E7: =IFERROR(ROUND(AVERAGEIFS(WasteLog[Waste cost],WasteLog[Date],$B7),2),0) -> 108.7
B8: 45845 | C8: =SUMIFS(OrderLines[LineNetAmount],OrderLines[OrderDateTime],$B8) -> 1619.6286 | D8: =IFERROR(AVERAGEIFS(Feedback[Rating],Feedback[Date],$B8),0) -> 4.75 | E8: =IFERROR(ROUND(AVERAGEIFS(WasteLog[Waste cost],WasteLog[Date],$B8),2),0) -> 74.07
B9: 45846 | C9: =SUMIFS(OrderLines[LineNetAmount],OrderLines[OrderDateTime],$B9) -> 425.1991 | D9: =IFERROR(AVERAGEIFS(Feedback[Rating],Feedback[Date],$B9),0) -> 4 | E9: =IFERROR(ROUND(AVERAGEIFS(WasteLog[Waste cost],WasteLog[Date],$B9),2),0) -> 35.32
B10: 45847 | C10: =SUMIFS(OrderLines[LineNetAmount],OrderLines[OrderDateTime],$B10) -> 2706.5737 | D10: =IFERROR(AVERAGEIFS(Feedback[Rating],Feedback[Date],$B10),0) -> 3.1666667 | E10: =IFERROR(ROUND(AVERAGEIFS(WasteLog[Waste cost],WasteLog[Date],$B10),2),0) -> 37.26
B11: 45848 | C11: =SUMIFS(OrderLines[LineNetAmount],OrderLines[OrderDateTime],$B11) -> 3654.4446 | D11: =IFERROR(AVERAGEIFS(Feedback[Rating],Feedback[Date],$B11),0) -> 4 | E11: =IFERROR(ROUND(AVERAGEIFS(WasteLog[Waste cost],WasteLog[Date],$B11),2),0) -> 8
B12: 45849 | C12: =SUMIFS(OrderLines[LineNetAmount],OrderLines[OrderDateTime],$B12) -> 3744.4975 | D12: =IFERROR(AVERAGEIFS(Feedback[Rating],Feedback[Date],$B12),0) -> 3.5 | E12: =IFERROR(ROUND(AVERAGEIFS(WasteLog[Waste cost],WasteLog[Date],$B12),2),0) -> 195.31
B13: 45850 | C13: =SUMIFS(OrderLines[LineNetAmount],OrderLines[OrderDateTime],$B13) -> 3559.4395 | D13: =IFERROR(AVERAGEIFS(Feedback[Rating],Feedback[Date],$B13),0) -> 4 | E13: =IFERROR(ROUND(AVERAGEIFS(WasteLog[Waste cost],WasteLog[Date],$B13),2),0) -> 143.24
B14: 45851 | C14: =SUMIFS(OrderLines[LineNetAmount],OrderLines[OrderDateTime],$B14) -> 2567.5368 | D14: =IFERROR(AVERAGEIFS(Feedback[Rating],Feedback[Date],$B14),0) -> 3.8 | E14: =IFERROR(ROUND(AVERAGEIFS(WasteLog[Waste cost],WasteLog[Date],$B14),2),0) -> 0
... B63: 45900 | C63: =SUMIFS(OrderLines[LineNetAmount],OrderLines[OrderDateTime],$B63) -> 0 | D63: =IFERROR(AVERAGEIFS(Feedback[Rating],Feedback[Date],$B63),0) -> 0 | E63: =IFERROR(ROUND(AVERAGEIFS(WasteLog[Waste cost],WasteLog[Date],$B63),2),0) -> 0

Sheet Menu (Day 6 Ans)
A1: SKU | B1: ItemName | C1: Category | D1: SupplierID | E1: UnitCost | F1: UnitPrice
A2: HXAJI0 | B2: Veg Thali | C2: Hot Meal | D2: S009 | E2: 96.22 | F2: 227.61
A3: HDPBHS | B3: Chicken Thali | C3: Hot Meal | D3: S001 | E3: 121.24 | F3: 256.91 | J3: SKU | K3: UnitCost
A4: HUZZPQ | B4: Rajma Chawal | C4: Hot Meal | D4: S005 | E4: 80.92 | F4: 146.4
A5: H3A3ZM | B5: Paneer Butter Masala + Naan | C5: Hot Meal | D5: S003 | E5: 74.07 | F5: 170.83 | J5: BOC6UZ | K5: =VLOOKUP($J$5,Menu[],MATCH($K$3,Menu[#Headers],0),FALSE) -> 11.84
A6: HH1DNM | B6: Egg Curry + Rice | C6: Hot Meal | D6: S006 | E6: 112.08 | F6: 246.09
A7: SV30T9 | B7: Samosa | C7: Snack | D7: S007 | E7: 15.51 | F7: 39.95
A8: SCKW5N | B8: Veg Sandwich | C8: Snack | D8: S004 | E8: 35.81 | F8: 70.54
A9: SZBIKC | B9: Paneer Roll | C9: Snack | D9: S004 | E9: 19.55 | F9: 38.06
A10: S5NQ4F | B10: Masala Puff | C10: Snack | D10: S006 | E10: 22.61 | F10: 50.19
A11: SHJ7XV | B11: Poha | C11: Snack | D11: S003 | E11: 25.8 | F11: 52.45
A12: BTIQJ7 | B12: Tea | C12: Beverage | D12: S009 | E12: 14.18 | F12: 30.34
A13: BHL1C3 | B13: Coffee | C13: Beverage | D13: S006 | E13: 9.38 | F13: 22.2
A14: BOC6UZ | B14: Masala Chaas | C14: Beverage | D14: S004 | E14: 11.84 | F14: 32.98
A15: BXO6QJ | B15: Nimbu Pani | C15: Beverage | D15: S004 | E15: 8 | F15: 20.11
A16: B0T0PV | B16: Bottled Water | C16: Beverage | D16: S006 | E16: 13.89 | F16: 28.43
A17: DH9SDB | B17: Gulab Jamun (2 pc) | C17: Dessert | D17: S002 | E17: 38.23 | F17: 76.55
... A20: DYTJXE | B20: Fruit Cup | C20: Dessert | D20: S007 | E20: 29.14 | F20: 57.07

Sheet Staff
A1: StaffID | B1: StaffName | C1: Role | D1: Branch | E1: HourlyRateINR
A2: E001 | B2: Tarun | C2: Cashier | D2: Plant 1 Canteen | E2: 151.58
A3: E002 | B3: Payal | C3: Cashier | D3: Head Office Café | E3: 129.61
A4: E003 | B4: Karan | C4: Cashier | D4: Head Office Café | E4: 100.98
A5: E004 | B5: Payal | C5: Cook | D5: Plant 1 Canteen | E5: 134.57
A6: E005 | B6: Vikram | C6: Cook | D6: Head Office Café | E6: 93.09
A7: E006 | B7: Rina | C7: Cashier | D7: Head Office Café | E7: 171.84
A8: E007 | B8: Sanjay | C8: Cook | D8: Plant 2 Canteen | E8: 113.29
A9: E008 | B9: Manish | C9: Cook | D9: Head Office Café | E9: 149.63
A10: E009 | B10: Pooja | C10: Server | D10: Head Office Café | E10: 118.05
A11: E010 | B11: Sourav | C11: Cashier | D11: Plant 1 Canteen | E11: 136.81
A12: E011 | B12: Neha | C12: Cashier | D12: Plant 2 Canteen | E12: 139.2
A13: E012 | B13: Amit | C13: Cook | D13: Head Office Café | E13: 106.64
... A19: E018 | B19: Payal | C19: Cashier | D19: Head Office Café | E19: 172.97

Sheet Inventory
A1: SKU | B1: OnHandQty | C1: ReorderPoint | D1: LeadTimeDays | E1: LastRestockDate | F1: ItemName
A2: HXAJI0 | B2: 198 | C2: 36 | D2: 3 | E2: 45876 | F2: =VLOOKUP(Inventory[[#This Row],[SKU]],Menu[],MATCH(Inventory[[#Headers],[ItemName]],Menu[#Headers],0),FALSE) -> Veg Thali
A3: HDPBHS | B3: 152 | C3: 30 | D3: 6 | E3: 45861 | F3: =VLOOKUP(Inventory[[#This Row],[SKU]],Menu[],MATCH(Inventory[[#Headers],[ItemName]],Menu[#Headers],0),FALSE) -> Chicken Thali
A4: HUZZPQ | B4: 120 | C4: 25 | D4: 6 | E4: 45882 | F4: =VLOOKUP(Inventory[[#This Row],[SKU]],Menu[],MATCH(Inventory[[#Headers],[ItemName]],Menu[#Headers],0),FALSE) -> Rajma Chawal
A5: H3A3ZM | B5: 130 | C5: 42 | D5: 4 | E5: 45864 | F5: =VLOOKUP(Inventory[[#This Row],[SKU]],Menu[],MATCH(Inventory[[#Headers],[ItemName]],Menu[#Headers],0),FALSE) -> Paneer Butter Masala + Naan
A6: HH1DNM | B6: 176 | C6: 46 | D6: 3 | E6: 45871 | F6: =VLOOKUP(Inventory[[#This Row],[SKU]],Menu[],MATCH(Inventory[[#Headers],[ItemName]],Menu[#Headers],0),FALSE) -> Egg Curry + Rice
A7: SV30T9 | B7: 81 | C7: 25 | D7: 3 | E7: 45868 | F7: =VLOOKUP(Inventory[[#This Row],[SKU]],Menu[],MATCH(Inventory[[#Headers],[ItemName]],Menu[#Headers],0),FALSE) -> Samosa
A8: SCKW5N | B8: 45 | C8: 57 | D8: 4 | E8: 45840 | F8: =VLOOKUP(Inventory[[#This Row],[SKU]],Menu[],MATCH(Inventory[[#Headers],[ItemName]],Menu[#Headers],0),FALSE) -> Veg Sandwich
A9: SZBIKC | B9: 89 | C9: 21 | D9: 5 | E9: 45864 | F9: =VLOOKUP(Inventory[[#This Row],[SKU]],Menu[],MATCH(Inventory[[#Headers],[ItemName]],Menu[#Headers],0),FALSE) -> Paneer Roll
A10: S5NQ4F | B10: 85 | C10: 41 | D10: 3 | E10: 45873 | F10: =VLOOKUP(Inventory[[#This Row],[SKU]],Menu[],MATCH(Inventory[[#Headers],[ItemName]],Menu[#Headers],0),FALSE) -> Masala Puff
